Workbook

Sheet LƯƠNG 
A2: TRƯỜNG TH -THCS- THPT ÂU VIỆT MỸ NỘI TRÚ - BÁN TRÚ - CHƯƠNG TRÌNH SONG NGỮ | J2: EUROPEAN - VIETNAMESE - AMERICAN PRIMARY - SECONDARY & HIGH SCHOOL BOARDING - SEMI BOARDING - BILINGUAL PROGRAM
A5: BẢNG TÍNH LƯƠNG NHÂN VIÊN FULLTIME THÁNG 03.2026
A6: STT | B6: HỌ TÊN | C6: ỦY QUYỀN | D6: CHỨC VỤ | E6: Ngày công bắt buộc | F6: LƯƠNG | I6: THU NHẬP TĂNG THÊM | N6: TỔNG | O6: GIẢM TRỪ | T6: THỰC NHẬN | U6: GHI CHÚ | W6: CÁCH TÍNH LƯƠNG
F7: LCB/ Lương dạy | G7: Kiêm nhiệm | H7: GVCN | I7: Vượt giờ dạy | J7: Hội đồng sư phạm | K7: Thu nhập khác | L7: Số ngày tăng ca | M7: Tiền tăng ca | O7: Trừ khác | P7: Ngày vắng | Q7: Trừ vắng | R7: BHXH 10,5% | S7: TNCN
A8: A | B8: NHÂN VIÊN CƠ HỮU ( KHÔNG THAM GIA BHXH) | X8: ='[1]chi tiết lương từng người '!J29 -> 0 | Y8: =T8-X8 -> 0
A9: 1 | B9: Lê Khánh Sơn | D9: Truyền thông | E9: 44 ca | F9: =#REF! -> #REF! | L9: 4.5 | M9: =F9/26*L9 -> #REF! | N9: =SUM(F9:K9)+M9 -> #REF! | T9: =N9-O9-Q9-R9-S9 -> #REF! | X9: ='[1]chi tiết lương từng người '!K29 -> 0 | Y9: =T9-X9 -> #REF!
A10: 2 | B10: Tiên Thị Ngọc Trân | D10: Truyền thông | F10: =#REF! -> #REF! | N10: =SUM(F10:K10)+M10 -> #REF! | T10: =N10-O10-Q10-R10-S10 -> #REF! | X10: ='[1]chi tiết lương từng người '!C29 -> 1076923.1 | Y10: =T10-X10 -> #REF!
A11: 3 | B11: Nguyễn Quốc Thịnh | C11: RỒI | D11: Truyền thông | F11: =#REF! -> #REF! | N11: =SUM(F11:K11)+M11 -> #REF! | P11: 16 | Q11: =F11/26*P11 -> #REF! | T11: =N11-O11-Q11-R11-S11 -> #REF! | U11: làm 8 ngày | V11: thử việc 23.3.26
A12: 4 | B12: Trần Thị Tây Thy | D12: thử việc kt | E12: 26 | F12: =#REF! -> #REF! | G12: =#REF! -> #REF! | N12: =SUM(F12:K12)+M12 -> #REF! | P12: =#REF! -> #REF! | Q12: =(F12+G12)/E12*P12 -> #REF! | T12: =N12-O12-Q12-R12-S12 -> #REF! | X12: ='[1]chi tiết lương từng người '!L29 -> 0 | Y12: =T12-X12 -> #REF!
A13: 5 | B13: Nguyễn Thị Mộng Bình | D13: Kế toán | E13: 26 | F13: =#REF! -> #REF! | N13: =SUM(F13:K13)+M13 -> #REF! | T13: =N13-O13-Q13-R13-S13 -> #REF! | X13: ='[1]chi tiết lương từng người '!M29 -> 0 | Y13: =T13-X13 -> #REF!
A14: 6 | B14: Nguyễn Hoàng Tỷ | D14: Trợ lý | F14: =#REF! -> #REF! | I14: =#REF! -> #REF! | J14: =#REF! -> #REF! | N14: =SUM(F14:K14)+M14 -> #REF! | T14: =N14-O14-Q14-R14-S14 -> #REF! | V14: bồi dưỡng | X14: ='[1]chi tiết lương từng người '!O29 -> #REF!
A15: 7 | B15: Nguyễn Quỳnh Vy | D15: thử việc qs | E15: 26 | F15: =#REF! -> #REF! | J15: =#REF! -> #REF! | L15: =2.5+2.25 -> 4.75 | M15: =F15/E15*L15 -> #REF! | N15: =SUM(F15:K15)+M15 -> #REF! | P15: =#REF! -> #REF! | Q15: =F15/E15*P15 -> #REF! | T15: =N15-O15-Q15-R15-S15 -> #REF! | V15: thử việc từ 2/2/26
A16: 8 | B16: Cao Trọng Quý | D16: thử việc qs | E16: 26 | F16: 6500000 | J16: =#REF! -> #REF! | N16: =SUM(F16:K16)+M16 -> #REF! | T16: =N16-O16-Q16-R16-S16 -> #REF! | V16: thử việc từ 2/3/26
A17: 9 | B17: Phạm Huy Trường | C17: RỒI | D17: BV | E17: 29 | F17: =#REF! -> #REF! | K17: =SUM(#REF!) -> #REF! | L17: =#REF! -> #REF! | M17: =F17/E17*L17 -> #REF! | N17: =SUM(F17:K17)+M17 -> #REF! | T17: =N17-O17-Q17-R17-S17 -> #REF!
A18: 10 | B18: Trần Trọng Tạo | C18: RỒI | D18: BV | E18: 29 | F18: =#REF! -> #REF! | G18: =#REF!+#REF! -> #REF! | K18: =SUM(#REF!) -> #REF! | L18: =#REF! -> #REF! | M18: =F18/E18*L18 -> #REF! | N18: =SUM(F18:K18)+M18 -> #REF! | T18: =N18-O18-Q18-R18-S18 -> #REF!
A19: 11 | B19: Lê Thị Phương | D19: Y TẾ | E19: 26 | F19: =#REF! -> #REF! | J19: =#REF! -> #REF! | K19: =#REF! -> #REF! | L19: 0.5 | M19: =F19/E19*L19 -> #REF! | N19: =SUM(F19:K19)+M19 -> #REF! | T19: =N19-O19-Q19-R19-S19 -> #REF!
A20: 12 | B20: Nguyễn Ngọc Hiếu | D20: TX | E20: 26 | F20: =#REF! -> #REF! | L20: 1.5 | M20: =F20/E20*L20 -> #REF! | N20: =SUM(F20:K20)+M20 -> #REF! | T20: =N20-O20-Q20-R20-S20 -> #REF!
A21: 13 | B21: Hà Hải Hưng | D21: TX | E21: 26 | F21: =#REF! -> #REF! | L21: =3.75+0.5 -> 4.25 | M21: =F21/E21*L21 -> #REF! | N21: =SUM(F21:K21)+M21 -> #REF! | P21: =#REF! -> #REF! | Q21: =F21/E21*P21 -> #REF! | T21: =N21-O21-Q21-R21-S21 -> #REF! | V21: 46076
A22: 14 | B22: Hồ Thị Vũ | D22: Tạp vụ | E22: 29 | F22: =#REF! -> #REF! | G22: =#REF! -> #REF! | J22: =#REF! -> #REF! | K22: =F22/E22*30%*1 -> #REF! | N22: =SUM(F22:K22)+M22 -> #REF! | T22: =N22-O22-Q22-R22-S22 -> #REF!
A23: 15 | B23: Nguyễn Thị Vân | D23: Tạp vụ | E23: 29 | F23: =#REF! -> #REF! | G23: =#REF! -> #REF! | J23: =#REF! -> #REF! | N23: =SUM(F23:K23)+M23 -> #REF! | T23: =N23-O23-Q23-R23-S23 -> #REF!
A24: 16 | B24: Nguyễn Lệ Hát | D24: Bếp | E24: 26 | F24: =#REF! -> #REF! | J24: =#REF! -> #REF! | K24: =SUM(#REF!) -> #REF! | M24: =F24/E24*L24 -> #REF! | N24: =SUM(F24:K24)+M24 -> #REF! | P24: 5 | Q24: =F24/E24*P24 -> #REF! | T24: =N24-O24-Q24-R24-S24 -> #REF!
A25: 17 | B25: Nguyễn Hoàng Minh | D25: thử việc vp, hóa | F25: 7000000 | N25: =SUM(F25:K25)+M25 -> 7000000 | P25: 20.5 | Q25: =F25/26*P25 -> 5519230.8 | T25: =N25-O25-Q25-R25-S25 -> 1480769.2 | U25: làm 5.5 ngày | V25: đã nghỉ
A26: TỔNG TIỀN NHÂN VIÊN CƠ HỮU ( KHÔNG THAM GIA BHXH) | U26: =SUM(T9:T25) -> #REF!
A27: B | B27: GIÁO VIÊN, NHÂN VIÊN ( THAM GIA BHXH) | T27: =N27-O27-Q27-R27-S27 -> 0 | X27: ='[1]chi tiết lương từng người '!J46 -> #REF! | Y27: =T27-X27 -> #REF!
A28: 18 | B28: Sơn Thị Thanh Hồng | C28: CHƯA | D28: PHT-GV Hoá | E28: 26 | F28: ='B. GV- NVCH'!G19 -> 4800000 | G28: ='B. GV- NVCH'!G7 -> 10000000 | H28: ='B. GV- NVCH'!G8 -> 2000000 | I28: ='B. GV- NVCH'!G20 -> -3000000 | J28: ='B. GV- NVCH'!G25 -> 200000 | K28: =SUM('B. GV- NVCH'!G26:G30) -> 354000 | N28: =SUM(F28:K28)+M28 -> 14354000 | R28: =5100000*10.5% -> 535500 | T28: =N28-O28-Q28-R28-S28 -> 13818500 | U28: THPT 11 | W28: nếu nghỉ, tăng ca thì tính trên mức 10tr PHT
A29: 19 | B29: Nguyễn Hoàng Minh | C29: RỒI | D29: TQS -QV lý | E29: 26 | F29: ='B. GV- NVCH'!M19 -> 4800000 | G29: ='B. GV- NVCH'!M7 -> 7000000 | H29: ='B. GV- NVCH'!M8 -> 2000000 | I29: ='B. GV- NVCH'!M20 -> -3000000 | J29: ='B. GV- NVCH'!M25 -> 200000 | K29: =SUM('B. GV- NVCH'!M26:M30) -> 412000 | N29: =SUM(F29:K29)+M29 -> 11412000 | R29: =5100000*10.5% -> 535500 | T29: =N29-O29-Q29-R29-S29 -> 10876500 | U29: THPT 12 | W29: nếu nghỉ, tăng ca thì tính trên mức 7tr QS
A30: 20 | B30: Lư Thị Bé Bay | C30: CHƯA | D30: TS - QLMN | E30: 26 | F30: =#REF! -> #REF! | G30: =SUM(#REF!) -> #REF! | J30: =#REF! -> #REF! | K30: =#REF! -> #REF! | L30: 0.5 | M30: =F30/26*L30 -> #REF! | N30: =SUM(F30:K30)+M30 -> #REF! | O30: 200000 | R30: =5100000*10.5% -> 535500 | T30: =N30-O30-Q30-R30-S30 -> #REF! | W30: ql bán trú 1tr, môi trường 500k, văn hóa doanh nghiệp 500k, KPI 3tr, ql zalo, fb 1000k, duy trì sĩ số 500k
A31: 21 | B31: Đặng Ái Diễm | C31: RỒI | D31: TS-QS | E31: 26 | F31: =#REF! -> #REF! | G31: =#REF! -> #REF! | I31: =#REF! -> #REF! | J31: =#REF! -> #REF! | K31: =#REF! -> #REF! | L31: 4.5 | M31: =F31/26*L31 -> #REF! | N31: =SUM(F31:K31)+M31 -> #REF! | R31: =5100000*10.5% -> 535500 | T31: =N31-O31-Q31-R31-S31 -> #REF! | W31: quản sinh, quản học tối 4tr, trang zalo, fb 500k, dv ăn uống 500k, công đoàn 1tr, duy trì sĩ số 500k, KPI 2tr
A32: 22 | B32: Nguyễn Thái Hiển | C32: CHƯA | D32: GV thể dục - CSVC | E32: 26 | F32: ='B. GV- NVCH'!S19 -> 4800000 | G32: ='B. GV- NVCH'!S7 -> 5000000 | J32: ='B. GV- NVCH'!S25 -> 200000 | L32: ='B. GV- NVCH'!P24 -> 1.5 | M32: =G32/E32*L32 -> 288461.54 | N32: =SUM(F32:K32)+M32 -> 10288462 | R32: =5100000*10.5% -> 535500 | T32: =N32-O32-Q32-R32-S32 -> 9752961.5 | W32: nếu nghỉ, tăng ca thì tính trên mức 5tr CSVC
A33: 23 | B33: Nguyễn Thị Ánh Phương | C33: CHƯA | D33: Phụ bếp | E33: 26 | F33: 5500000 | J33: ='B. GV- NVCH'!#REF! -> #REF! | K33: =SUM('B. GV- NVCH'!#REF!) -> #REF! | N33: =SUM(F33:K33)+M33 -> #REF! | R33: =5100000*10.5% -> 535500 | T33: =N33-O33-Q33-R33-S33 -> #REF!
A34: 24 | B34: Phạm Hoàng Yến | C34: CHƯA | D34: Thủ quỹ | E34: 26 | F34: 5000000 | G34: 1700000 | J34: ='B. GV- NVCH'!#REF! -> #REF! | N34: =SUM(F34:K34)+M34 -> #REF! | R34: =5100000*10.5% -> 535500 | T34: =N34-O34-Q34-R34-S34 -> #REF!
A35: 25 | B35: Mạch Tô Ngọc Hân | C35: RỒI | D35: GV - Văn | F35: ='B. GV- NVCH'!Y19 -> 4800000 | G35: ='B. GV- NVCH'!Y7+'B. GV- NVCH'!Y9 -> 1700000 | H35: ='B. GV- NVCH'!Y8 -> 2000000 | I35: ='B. GV- NVCH'!Y20 -> 1200000 | J35: ='B. GV- NVCH'!Y25 -> 200000 | K35: =SUM('B. GV- NVCH'!Y26:Y30) -> 2068333.1 | N35: =SUM(F35:K35)+M35 -> 11968333 | R35: =5100000*10.5% -> 535500 | S35: ='B. GV- NVCH'!Y34 -> 37642 | T35: =N35-O35-Q35-R35-S35 -> 11395191 | U35: THPT 8,9 NKCT 9A1 | W35: viết bài quảng cáo 500k, hỗ trợ giám thì và tư vấn tâm lý 300k/ tuần
A36: 26 | B36: Nguyễn Minh Khoa | C36: CHƯA | D36: BTĐ -GV Văn | F36: ='B. GV- NVCH'!AE19 -> 4800000 | G36: ='B. GV- NVCH'!AE7 -> 4000000 | H36: ='B. GV- NVCH'!AE8 -> 2000000 | I36: =SUM('B. GV- NVCH'!AE20:AE22) -> 4144000 | K36: =SUM('B. GV- NVCH'!AE26:AE30) -> 2450000 | N36: =SUM(F36:K36)+M36 -> 17394000 | R36: =5100000*10.5% -> 535500 | T36: =N36-O36-Q36-R36-S36 -> 16858500 | U36: THPT 10 | W36: bí thư đoàn trường 4 triệu
A37: 27 | B37: Trần Hoàng Khiếm | C37: RỒI | D37: P. BTĐ -GV địa | F37: ='B. GV- NVCH'!AK19 -> 4800000 | G37: ='B. GV- NVCH'!AK7 -> 1000000 | H37: ='B. GV- NVCH'!AK8 -> 1000000 | I37: ='B. GV- NVCH'!AK20 -> -1300000 | J37: ='B. GV- NVCH'!AK25 -> 200000 | K37: =SUM('B. GV- NVCH'!AK26:AK29) -> 2487333.1 | N37: =SUM(F37:K37)+M37 -> 8187333.1 | R37: =5100000*10.5% -> 535500 | T37: =N37-O37-Q37-R37-S37 -> 7651833.1 | U37: NKCT 7A2 | W37: phó bí thư 1tr
A38: 28 | B38: Trần Thị Kim Anh | C38: RỒI | D38: GV- Toán | F38: ='B. GV- NVCH'!AQ10 -> 0 | G38: ='B. GV- NVCH'!AQ7 -> 0 | J38: ='B. GV- NVCH'!AQ25 -> 200000 | K38: =SUM('B. GV- NVCH'!AQ26:AQ30) -> 216000 | N38: =SUM(F38:K38)+M38 -> 416000 | R38: =5100000*10.5% -> 535500 | T38: =N38-O38-Q38-R38-S38 -> -119500
A39: 29 | B39: Lê Thị Thùy Trang | C39: RỒI | D39: GV- AV | F39: ='B. GV- NVCH'!AW10 -> 0 | H39: ='B. GV- NVCH'!AW8 -> 1000000 | J39: ='B. GV- NVCH'!AW25 -> 200000 | K39: =SUM('B. GV- NVCH'!AW26:AW29) -> 950000 | N39: =SUM(F39:K39)+M39 -> 2150000 | R39: =5100000*10.5% -> 535500 | T39: =N39-O39-Q39-R39-S39 -> 1614500 | U39: THPT 6,7 | W39: lương cơ hữu 4,8tr đảm bảo dạy tất cả mọi nơi AVM cộng lại ( nếu không đủ sẽ trả thêm phần tiền thiếu)
A40: 30 | B40: Lê Kim Oanh | C40: RỒI | D40: GV AV | F40: ='B. GV- NVCH'!BC10 -> 0 | H40: ='B. GV- NVCH'!BC8 -> 1000000 | J40: ='B. GV- NVCH'!BC25 -> 200000 | K40: =SUM('B. GV- NVCH'!BC26:BC30) -> 1383333.1 | N40: =SUM(F40:K40)+M40 -> 2583333.1 | R40: =5100000*10.5% -> 535500 | T40: =N40-O40-Q40-R40-S40 -> 2047833.1 | U40: NKCT 9A2 | W40: lương cơ hữu 4,8tr đảm bảo dạy tất cả mọi nơi AVM cộng lại ( nếu không đủ sẽ trả thêm phần tiền thiếu)
A41: 31 | B41: Phạm Đa Hiền Thư | C41: RỒI | D41: GV- AV | F41: ='B. GV- NVCH'!BI10 -> 0 | G41: ='B. GV- NVCH'!BI7 -> 1000000 | H41: ='B. GV- NVCH'!BI8 -> 1000000 | J41: ='B. GV- NVCH'!BI25 -> 200000 | K41: =SUM('B. GV- NVCH'!BI26:BI30) -> 730000 | N41: =SUM(F41:K41)+M41 -> 2930000 | R41: =5100000*10.5% -> 535500 | T41: =N41-O41-Q41-R41-S41 -> 2394500 | U41: NKCT 12 | W41: kiêm nhiệm Tổ trưởng AV 1tr lương cơ hữu 4,8tr đảm bảo dạy tất cả mọi nơi AVM cộng lại ( nếu không đủ sẽ trả thêm phần tiền thiếu)
A42: 32 | B42: Nguyễn Minh Đức | C42: 2 NƠI | D42: GV - VL | F42: ='B. GV- NVCH'!BO10 -> 0 | J42: ='B. GV- NVCH'!BO25 -> 200000 | K42: =SUM('B. GV- NVCH'!BO26:BO30) -> 188000 | N42: =SUM(F42:K42)+M42 -> 388000 | R42: =5100000*32% -> 1632000 | S42: ='B. GV- NVCH'!BO34 -> 0 | T42: =N42-O42-Q42-R42-S42 -> -1244000 | U42: nhờ đóng BHXH dùm
A43: 33 | B43: Nguyễn Thị Bé Chính | C43: RỒI | D43: GV _Toán | F43: ='B. GV- NVCH'!BU10 -> 3376000 | G43: ='B. GV- NVCH'!BU7 -> 1000000 | J43: ='B. GV- NVCH'!BU25 -> 200000 | K43: =SUM('B. GV- NVCH'!BU26:BU30) -> 490000 | N43: =SUM(F43:K43)+M43 -> 5066000 | R43: =5100000*32% -> 1632000 | T43: =N43-O43-Q43-R43-S43 -> 3434000 | U43: nhờ đóng BHXH dùm
...

Sheet B. GV- NVCH
A2: STT | C2: 1 | I2: 2 | O2: 3 | U2: 4 | AA2: 5 | AG2: 6 | AM2: 7 | AS2: 8 | AY2: 9 | BE2: 10 | BK2: 11 | BQ2: 12 | BW2: 13
B3: TÊN NHÂN VIÊN | C3: SƠN THỊ THANH HỒNG | I3: NGUYỄN HOÀNG MINH | O3: NGUYỄN THÁI HIỂN | U3: MẠCH TÔ NGỌC HÂN | AA3: NGUYỄN MINH KHOA | AG3: TRẦN HOÀNG KHIẾM | AM3: TRẦN THỊ KIM ANH | AS3: LÊ THỊ THÙY TRANG | AY3: LÊ KIM OANH | BE3: PHẠM ĐA HIỀN THƯ | BK3: NGUYỄN MINH ĐỨC | BQ3: NGUYỄN THỊ BÉ CHÍNH | BW3: ĐOÀN THỊ THƯƠNG THẢO
B4: CHỨC VỤ | C4: PHÓ HIỆU TRƯỞNG | I4: QUẢN SINH - GV LÝ | O4: CSVC -QV THỂ DỤC | U4: GV VĂN | AA4: BÍ THƯ ĐOÀN - GV VĂN | AG4: PHÓ BÍ THƯ ĐOÀN - GV ĐỊA | AM4: GV TOÁN | AS4: GV AV | AY4: GV AV | BE4: GV AV | BK4: GV -LÝ | BQ4: GV TOÁN | BW4: GV AV
C5: ĐG | D5: SL THPT | E5: SL NKCT | F5: SL BDVH | G5: TIỀN | H5: GHI CHÚ | I5: ĐG | J5: SL THPT | K5: SL NKCT | L5: SL BDVH | M5: TIỀN | N5: GHI CHÚ | O5: ĐG | P5: SL THPT | Q5: SL NKCT | R5: SL BDVH | S5: TIỀN | T5: GHI CHÚ | U5: ĐG | V5: SL THPT | W5: SL NKCT | X5: SL BDVH | Y5: TIỀN | Z5: GHI CHÚ | AA5: ĐG | AB5: SL THPT | AC5: SL NKCT | AD5: SL BDVH | AE5: TIỀN | AF5: GHI CHÚ | AG5: ĐG | AH5: SL THPT | AI5: SL NKCT | AJ5: SL BDVH | AK5: TIỀN | AL5: GHI CHÚ | AM5: ĐG | AN5: SL THPT | AO5: SL NKCT | AP5: SL BDVH | AQ5: TIỀN | AR5: GHI CHÚ | AS5: ĐG | AT5: SL THPT | AU5: SL NKCT | AV5: SL BDVH | AW5: TIỀN | AX5: GHI CHÚ | AY5: ĐG | AZ5: SL THPT | BA5: SL NKCT | BB5: SL BDVH | BC5: TIỀN | BD5: GHI CHÚ | BE5: ĐG | BF5: SL THPT | BG5: SL NKCT | BH5: SL BDVH | BI5: TIỀN | BJ5: GHI CHÚ | BK5: ĐG | BL5: SL THPT | BM5: SL NKCT | BN5: SL BDVH | BO5: TIỀN | BP5: GHI CHÚ | BQ5: ĐG | BR5: SL THPT | BS5: SL NKCT | BT5: SL BDVH | BU5: TIỀN | BV5: GHI CHÚ | BW5: ĐG | BX5: SL THPT | BY5: SL NKCT | BZ5: SL BDVH | CA5: TIỀN | CB5: GHI CHÚ
A6: 1 | B6: LƯƠNG CHỨC VỤ, KIÊM NHIỆM | G6: =SUM(G7:G9) -> 12000000 | H6: =SUM(H7:H8) -> 0 | M6: =SUM(M7:M9) -> 9000000 | N6: =SUM(N7:N8) -> 0 | S6: =SUM(S7:S9) -> 5000000 | T6: =SUM(T7:T8) -> 0 | Y6: =SUM(Y7:Y9) -> 3700000 | Z6: =SUM(Z7:Z8) -> 0 | AE6: =SUM(AE7:AE9) -> 6000000 | AF6: =SUM(AF7:AF8) -> 0 | AK6: =SUM(AK7:AK9) -> 2000000 | AL6: =SUM(AL7:AL8) -> 0 | AQ6: =SUM(AQ7:AQ8) -> 0 | AR6: =SUM(AR7:AR8) -> 0 | AW6: =SUM(AW7:AW9) -> 1000000 | AX6: =SUM(AX7:AX8) -> 0 | BC6: =SUM(BC7:BC9) -> 1000000 | BD6: =SUM(BD7:BD8) -> 0 | BI6: =SUM(BI7:BI9) -> 2000000 | BJ6: =SUM(BJ7:BJ8) -> 0 | BO6: =SUM(BO7:BO9) -> 0 | BP6: =SUM(BP7:BP8) -> 0 | BU6: =SUM(BU7:BU9) -> 1000000 | BV6: =SUM(BV7:BV8) -> 0 | CA6: =SUM(CA7:CA9) -> 0 | CB6: =SUM(CB7:CB8) -> 0
A7: 1.1 | B7: Lương chức vụ | G7: 10000000 | M7: 7000000 | S7: 5000000 | Y7: 500000 | Z7: viết bài QC | AE7: 4000000 | AF7: bí thư đoàn | AK7: 1000000 | AL7: phó bí thư đoàn | BI7: 1000000 | BJ7: tổ trường AV | BU7: 1000000 | BV7: tổ trưởng toán
A8: 1.2 | B8: Kiêm nhiệm GVCN | G8: 2000000 | H8: THPT L11 | M8: 2000000 | N8: THPT L12 | Y8: =1000000+1000000 -> 2000000 | Z8: THPT L8,9 NKCT 9A1 | AE8: 2000000 | AF8: THPT L10 | AK8: 1000000 | AL8: NKCT 7A2 | AW8: 1000000 | AX8: THPT L6,7 | BC8: 1000000 | BD8: NKCT 9A2 | BI8: 1000000 | BJ8: NKCT L12
A9: 1.3 | B9: Kiêm nhiệm khác | Y9: 1200000 | Z9: hỗ trợ giám thị
A10: 2 | B10: LƯƠNG TIẾT DẠY - TRƯỜNG THPT | D10: =SUM(D11:D19) -> 0 | E10: =SUM(E11:E19) -> 0 | F10: =SUM(F11:F19) -> 0 | G10: =SUM(G11:G20) -> 1800000 | H10: =D10+E10+F10 -> 0 | J10: =SUM(J11:J19) -> 0 | K10: =SUM(K11:K19) -> 0 | L10: =SUM(L11:L19) -> 0 | M10: =SUM(M11:M20) -> 1800000 | N10: =J10+K10+L10 -> 0 | P10: =SUM(P11:P19) -> 14 | Q10: =SUM(Q11:Q19) -> 0 | R10: =SUM(R11:R19) -> 0 | S10: =SUM(S11:S20) -> 4800000 | T10: =P10+Q10+R10 -> 14 | V10: =SUM(V11:V19) -> 6 | W10: =SUM(W11:W19) -> 54 | X10: =SUM(X11:X19) -> 0 | Y10: =SUM(Y11:Y20) -> 6000000 | Z10: =V10+W10+X10 -> 60 | AB10: =SUM(AB11:AB22) -> 10 | AC10: =SUM(AC11:AC19) -> 50 | AD10: =SUM(AD11:AD19) -> 0 | AE10: =SUM(AE11:AE22) -> 8944000 | AF10: =AB10+AC10+AD10 -> 60 | AH10: =SUM(AH11:AH19) -> 6 | AI10: =SUM(AI11:AI19) -> 29 | AJ10: =SUM(AJ11:AJ19) -> 0 | AK10: =SUM(AK11:AK20) -> 3500000 | AL10: =AH10+AI10+AJ10 -> 35 | AN10: =SUM(AN11:AN19) -> 0 | AO10: =SUM(AO11:AO19) -> 12 | AP10: =SUM(AP11:AP19) -> 0 | AQ10: =SUM(AQ11:AQ20) -> 0 | AR10: =AN10+AO10+AP10 -> 12 | AT10: =SUM(AT11:AT19) -> 0 | AU10: =SUM(AU11:AU19) -> 24 | AV10: =SUM(AV11:AV19) -> 0 | AW10: =SUM(AW11:AW20) -> 0 | AX10: =AT10+AU10+AV10 -> 24 | AZ10: =SUM(AZ11:AZ19) -> 0 | BA10: =SUM(BA11:BA19) -> 44 | BB10: =SUM(BB11:BB19) -> 0 | BC10: =SUM(BC11:BC20) -> 0 | BD10: =AZ10+BA10+BB10 -> 44 | BF10: =SUM(BF11:BF19) -> 0 | BG10: =SUM(BG11:BG19) -> 44 | BH10: =SUM(BH11:BH19) -> 0 | BI10: =SUM(BI11:BI20) -> 0 | BJ10: =BF10+BG10+BH10 -> 44 | BL10: =SUM(BL11:BL19) -> 0 | BM10: =SUM(BM11:BM19) -> 16 | BN10: =SUM(BN11:BN19) -> 0 | BO10: =SUM(BO11:BO20) -> 0 | BP10: =BL10+BM10+BN10 -> 16 | BR10: =SUM(BR11:BR19) -> 0 | BS10: =SUM(BS11:BS19) -> 0 | BT10: =SUM(BT11:BT19) -> 0 | BU10: =SUM(BU11:BU22) -> 3376000 | BV10: =BR10+BS10+BT10 -> 0 | BX10: =SUM(BX11:BX22) -> 6 | BY10: =SUM(BY11:BY22) -> 0 | BZ10: =SUM(BZ11:BZ22) -> 12 | CA10: =SUM(CA11:CA22) -> 1648000 | CB10: =BX10+BY10+BZ10 -> 18
A11: 2.1 | B11: Tiểu học ( lớp 1,2,3,4,5): | C11: 60000 | H11: Từ T3/26 tiết cơ hữu là 30 tiết | I11: 60000 | N11: Từ T3/26 tiết cơ hữu là 30 tiết | O11: 60000 | T11: Tiết cơ hữu là 48 tiết | U11: 60000 | Z11: Từ T3/26 tiết cơ hữu là 48 tiết | AA11: 60000 | AF11: Tiết cơ hữu là 48 tiết | AG11: 60000 | AL11: Tiết cơ hữu là 48 tiết | AM11: 60000 | AQ11: =AM11*(AN11+AO11+AP11) -> 0 | AR11: CƠ HỮU DẠY NHIÊU TÍNH NHIÊU | AS11: 60000 | AW11: =AS11*(AT11+AU11+AV11) -> 0 | AX11: CƠ HỮU -đảm bảo lương 4,8tr/tháng (các nơi AVM cộng lại) | AY11: 60000 | BC11: =AY11*(AZ11+BA11+BB11) -> 0 | BD11: CƠ HỮU -đảm bảo lương 4,8tr/tháng (các nơi AVM cộng lại) | BE11: 60000 | BI11: =BE11*(BF11+BG11+BH11) -> 0 | BJ11: CƠ HỮU -đảm bảo lương 4,8tr/tháng (các nơi AVM cộng lại) | BK11: 60000 | BO11: =BK11*(BL11+BM11+BN11) -> 0 | BP11: Thỉnh giảng nhờ Trường đóng BHXH dùm | BQ11: 60000 | BU11: =BQ11*(BR11+BS11+BT11) -> 0 | BV11: Thỉnh giảng nhờ Trường đóng BHXH dùm | BW11: 60000 | CA11: =BW11*(BX11+BY11+BZ11) -> 0 | CB11: Thỉnh giảng nhờ Trường đóng BHXH dùm
A12: 2.2 | B12: THCS (lớp 6,7,8): | W12: =27+14 -> 41 | AI12: =3+7+7 -> 17 | AQ12: =AM12*(AN12+AO12+AP12) -> 0 | AU12: =12+12 -> 24 | AW12: =AS12*(AT12+AU12+AV12) -> 0 | BA12: =10+10+11 -> 31 | BC12: =AY12*(AZ12+BA12+BB12) -> 0 | BI12: =BE12*(BF12+BG12+BH12) -> 0 | BO12: =BK12*(BL12+BM12+BN12) -> 0 | BU12: =BQ12*(BR12+BS12+BT12) -> 0 | CA12: =BW12*(BX12+BY12+BZ12) -> 0
A13: 2.3 | B13: THCS (lớp 9): | W13: 13 | AC13: 12 | AI13: 6 | AQ13: =AM13*(AN13+AO13+AP13) -> 0 | AW13: =AS13*(AT13+AU13+AV13) -> 0 | BC13: =AY13*(AZ13+BA13+BB13) -> 0 | BI13: =BE13*(BF13+BG13+BH13) -> 0 | BM13: 8 | BO13: =BK13*(BL13+BM13+BN13) -> 0 | BU13: =BQ13*(BR13+BS13+BT13) -> 0 | CA13: =BW13*(BX13+BY13+BZ13) -> 0
A14: 2.4 | B14: THPT (lớp 10,11): | AC14: 26 | AO14: 12 | AQ14: =AM14*(AN14+AO14+AP14) -> 0 | AW14: =AS14*(AT14+AU14+AV14) -> 0 | BA14: 13 | BC14: =AY14*(AZ14+BA14+BB14) -> 0 | BG14: 30 | BI14: =BE14*(BF14+BG14+BH14) -> 0 | BO14: =BK14*(BL14+BM14+BN14) -> 0 | BU14: =BQ14*(BR14+BS14+BT14) -> 0 | CA14: =BW14*(BX14+BY14+BZ14) -> 0
A15: 2.5 | B15: THPT (lớp 12): | AC15: 12 | AI15: 6 | AQ15: =AM15*(AN15+AO15+AP15) -> 0 | AW15: =AS15*(AT15+AU15+AV15) -> 0 | BC15: =AY15*(AZ15+BA15+BB15) -> 0 | BG15: 14 | BI15: =BE15*(BF15+BG15+BH15) -> 0 | BM15: 8 | BO15: =BK15*(BL15+BM15+BN15) -> 0 | BU15: =BQ15*(BR15+BS15+BT15) -> 0 | CA15: =BW15*(BX15+BY15+BZ15) -> 0
A16: 2.6 | B16: Hoạt động ngoại khóa | C16: 100000 | I16: 100000 | O16: 100000 | U16: 100000 | V16: 6 | AA16: 100000 | AB16: 10 | AG16: 100000 | AH16: 6 | AM16: 100000 | AQ16: =AM16*(AN16+AO16+AP16) -> 0 | AS16: 100000 | AW16: =AS16*(AT16+AU16+AV16) -> 0 | AY16: 100000 | BC16: =AY16*(AZ16+BA16+BB16) -> 0 | BE16: 100000 | BI16: =BE16*(BF16+BG16+BH16) -> 0 | BK16: 100000 | BO16: =BK16*(BL16+BM16+BN16) -> 0 | BQ16: 100000 | BU16: =BQ16*(BR16+BS16+BT16) -> 0 | BW16: 100000 | BX16: 6 | CA16: =BW16*(BX16+BY16+BZ16) -> 600000
A17: 2.7 | B17: Quản học (70% lương của tiết học) | AQ17: =AM17*(AN17+AO17+AP17) -> 0 | AW17: =AS17*(AT17+AU17+AV17) -> 0 | AY17: 70000 | BC17: =AY17*(AZ17+BA17+BB17) -> 0 | BI17: =BE17*(BF17+BG17+BH17) -> 0 | BO17: =BK17*(BL17+BM17+BN17) -> 0 | BU17: =BQ17*(BR17+BS17+BT17) -> 0 | CA17: =BW17*(BX17+BY17+BZ17) -> 0
A18: 2.8 | B18: Quy đổi ngày công sang tiết (nửa ngày/2 tiết|) | P18: =3.5*4 -> 14 | T18: đổi 3.5 ngày
A19: 2.9 | B19: Lương dạy ( đủ đk nhận lương cơ hữu) | G19: =4800000 -> 4800000 | H19: 30 | M19: =4800000 -> 4800000 | N19: 30 | S19: =4800000 -> 4800000 | T19: 48 | Y19: =4800000 -> 4800000 | Z19: 48 | AE19: =4800000 -> 4800000 | AF19: 48 | AK19: =4800000 -> 4800000 | AL19: 48 | AQ19: =AM19*(AN19+AO19+AP19) -> 0 | AW19: =AS19*(AT19+AU19+AV19) -> 0 | BC19: =AY19*(AZ19+BA19+BB19) -> 0 | BI19: =BE19*(BF19+BG19+BH19) -> 0 | BO19: =BK19*(BL19+BM19+BN19) -> 0 | BU19: =BQ19*(BR19+BS19+BT19) -> 0 | CA19: =BW19*(BX19+BY19+BZ19) -> 0
A20: 2.10 | B20: Số tiết dư được tạm ứng | C20: 100000 | D20: =D10-30 -> -30 | G20: =D20*C20 -> -3000000 | H20: =H10-H19 -> -30 | I20: 100000 | J20: =J10-30 -> -30 | M20: =I20*J20 -> -3000000 | N20: =N10-N19 -> -30 | O20: 100000 | T20: =T10-T19 -> -34 | U20: 100000 | Y20: =U20*Z20 -> 1200000 | Z20: =Z10-Z19 -> 12 | AA20: 100000 | AE20: =AA20*AF20 -> 1200000 | AF20: =AF10-AF19 -> 12 | AG20: 100000 | AK20: =AG20*AL20 -> -1300000 | AL20: =AL10-AL19 -> -13 | AM20: 100000 | AQ20: =AM20*(AN20+AO20+AP20) -> 0 | AS20: 100000 | AW20: =AS20*(AT20+AU20+AV20) -> 0 | AY20: 100000 | BC20: =AY20*(AZ20+BA20+BB20) -> 0 | BE20: 100000 | BI20: =BE20*(BF20+BG20+BH20) -> 0 | BK20: 100000 | BO20: =BK20*(BL20+BM20+BN20) -> 0 | BQ20: 100000 | BU20: =BQ20*(BR20+BS20+BT20) -> 0 | BW20: 100000 | CA20: =BW20*(BX20+BY20+BZ20) -> 0
B21: Bồi dưỡng văn hóa | AA21: 64000 | AD21: 16 | AE21: =AA21*AD21 -> 1024000 | AF21: lớp 9 | BQ21: 100000 | BT21: 10 | BU21: =BQ21*BT21 -> 1000000 | BV21: lớp 11 (6hs) | BW21: 70000 | BZ21: 4 | CA21: =BW21*BZ21 -> 280000 | CB21: lớp 8 ( 6hs)
B22: Bồi dưỡng văn hóa | AA22: 120000 | AD22: 16 | AE22: =AA22*AD22 -> 1920000 | AF22: lớp 12 | BQ22: 132000 | BT22: 18 | BU22: =BQ22*BT22 -> 2376000 | BV22: lớp 12 (11hs) | BW22: 96000 | BZ22: 8 | CA22: =BW22*BZ22 -> 768000 | CB22: lớp 12 (5hs)
A23: 3 | B23: THU NHẬP TĂNG THÊM | D23: =SUM(D24:D33) -> 58 | E23: =SUM(E24:E33) -> 0 | F23: =SUM(F24:F33) -> 0 | G23: =SUM(G24:G30) -> 554000 | J23: =SUM(J24:J33) -> 87 | K23: =SUM(K24:K33) -> 0 | L23: =SUM(L24:L33) -> 0 | M23: =SUM(M24:M30) -> 612000 | P23: =SUM(P24:P33) -> 2.5 | Q23: =SUM(Q24:Q33) -> 0 | R23: =SUM(R24:R33) -> 0 | S23: =SUM(S24:S29) -> 488461.54 | V23: =SUM(V24:V33) -> 204.33333 | W23: =SUM(W24:W33) -> 0 | X23: =SUM(X24:X33) -> 0 | Y23: =SUM(Y24:Y30) -> 2268333.1 | AC23: =SUM(AC24:AC33) -> 0 | AD23: =SUM(AD24:AD33) -> 0 | AE23: =SUM(AE24:AE30) -> 2450000 | AI23: =SUM(AI24:AI33) -> 0 | AJ23: =SUM(AJ24:AJ33) -> 0 | AK23: =SUM(AK24:AK30) -> 2687333.1 | AO23: =SUM(AO24:AO33) -> 0 | AP23: =SUM(AP24:AP33) -> 0 | AQ23: =SUM(AQ24:AQ30) -> 416000 | AT23: =SUM(AT24:AT33) -> 98 | AU23: =SUM(AU24:AU33) -> 0 | AV23: =SUM(AV24:AV33) -> 0 | AW23: =SUM(AW24:AW30) -> 1150000 | AZ23: =SUM(AZ24:AZ33) -> 79.33333 | BA23: =SUM(BA24:BA33) -> 0 | BB23: =SUM(BB24:BB33) -> 0 | BC23: =SUM(BC24:BC30) -> 1583333.1 | BG23: =SUM(BG24:BG33) -> 0 | BH23: =SUM(BH24:BH33) -> 0 | BI23: =SUM(BI24:BI30) -> 930000 | BL23: =SUM(BL24:BL33) -> 47 | BM23: =SUM(BM24:BM33) -> 0 | BN23: =SUM(BN24:BN33) -> 0 | BO23: =SUM(BO24:BO30) -> 388000 | BR23: =SUM(BR24:BR33) -> 150 | BS23: =SUM(BS24:BS33) -> 0 | BT23: =SUM(BT24:BT33) -> 0 | BU23: =SUM(BU24:BU30) -> 690000 | BX23: =SUM(BX24:BX33) -> 38 | BY23: =SUM(BY24:BY33) -> 0 | BZ23: =SUM(BZ24:BZ33) -> 0 | CA23: =SUM(CA24:CA30) -> 370000
A24: 3.1 | B24: Tăng ca làm thêm công | O24: =S7/26 -> 192307.69 | P24: 1.5 | S24: =O24*SUM(P24:R24) -> 288461.54 | AE24: =AA24*SUM(AB24:AD24) -> 0 | AK24: =AG24*SUM(AH24:AJ24) -> 0 | AQ24: =AM24*SUM(AN24:AP24) -> 0 | AW24: =AS24*SUM(AT24:AV24) -> 0 | BC24: =AY24*SUM(AZ24:BB24) -> 0 | BI24: =BE24*SUM(BF24:BH24) -> 0 | BO24: =BK24*SUM(BL24:BN24) -> 0 | BU24: =BQ24*SUM(BR24:BT24) -> 0 | CA24: =BW24*SUM(BX24:BZ24) -> 0
A25: 3.2 | B25: Họp hội đồng sư phạm | C25: 200000 | D25: 1 | G25: =C25*SUM(D25:F25) -> 200000 | I25: 200000 | J25: 1 | M25: =I25*SUM(J25:L25) -> 200000 | O25: 200000 | P25: 1 | S25: =O25*SUM(P25:R25) -> 200000 | U25: 200000 | V25: 1 | Y25: =U25*SUM(V25:X25) -> 200000 | AA25: 200000 | AB25: 0 | AE25: =AA25*SUM(AB25:AD25) -> 0 | AF25: ko | AG25: 200000 | AH25: 1 | AK25: =AG25*SUM(AH25:AJ25) -> 200000 | AM25: 200000 | AN25: 1 | AQ25: =AM25*SUM(AN25:AP25) -> 200000 | AS25: 200000 | AT25: 1 | AW25: =AS25*SUM(AT25:AV25) -> 200000 | AY25: 200000 | AZ25: 1 | BC25: =AY25*SUM(AZ25:BB25) -> 200000 | BE25: 200000 | BF25: 1 | BI25: =BE25*SUM(BF25:BH25) -> 200000 | BK25: 200000 | BL25: 1 | BO25: =BK25*SUM(BL25:BN25) -> 200000 | BQ25: 200000 | BR25: 1 | BU25: =BQ25*SUM(BR25:BT25) -> 200000 | BW25: 200000 | BX25: 1 | CA25: =BW25*SUM(BX25:BZ25) -> 200000
A26: 3.3 | B26: Gác thi (70%/LCB tiết dạy) ( hỏi lại) | C26: =70%*100000 -> 70000 | G26: =C26*SUM(D26:F26) -> 0 | I26: =70%*100000 -> 70000 | M26: =I26*SUM(J26:L26) -> 0 | O26: =70%*100000 -> 70000 | S26: =O26*SUM(P26:R26) -> 0 | U26: =70%*100000 -> 70000 | V26: 11.33333 | Y26: =U26*SUM(V26:X26) -> 793333.1 | AA26: =70%*100000 -> 70000 | AB26: 8 | AE26: =AA26*SUM(AB26:AD26) -> 560000 | AG26: =70%*100000 -> 70000 | AH26: 18.33333 | AK26: =AG26*SUM(AH26:AJ26) -> 1283333.1 | AM26: =70%*100000 -> 70000 | AQ26: =AM26*SUM(AN26:AP26) -> 0 | AS26: =70%*100000 -> 70000 | AT26: 9 | AW26: =AS26*SUM(AT26:AV26) -> 630000 | AY26: =70%*100000 -> 70000 | AZ26: 7.33333 | BC26: =AY26*(AZ26+BA26+BB26) -> 513333.1 | BE26: =70%*100000 -> 70000 | BI26: =BE26*SUM(BF26:BH26) -> 0 | BK26: =70%*100000 -> 70000 | BO26: =BK26*SUM(BL26:BN26) -> 0 | BQ26: =70%*100000 -> 70000 | BU26: =BQ26*SUM(BR26:BT26) -> 0 | BW26: =70%*100000 -> 70000 | CA26: =BW26*SUM(BX26:BZ26) -> 0
A27: 3.4 | B27: Chấm bài tự luận : | C27: 5000 | G27: =C27*SUM(D27:F27) -> 0 | I27: 5000 | M27: =I27*SUM(J27:L27) -> 0 | O27: 5000 | S27: =O27*SUM(P27:R27) -> 0 | U27: 5000 | V27: 185 | Y27: =U27*SUM(V27:X27) -> 925000 | AA27: 5000 | AB27: 288 | AE27: =AA27*SUM(AB27:AD27) -> 1440000 | AG27: 5000 | AK27: =AG27*SUM(AH27:AJ27) -> 0 | AM27: 5000 | AQ27: =AM27*SUM(AN27:AP27) -> 0 | AS27: 5000 | AW27: =AS27*SUM(AT27:AV27) -> 0 | AY27: 5000 | BC27: =AY27*SUM(AZ27:BB27) -> 0 | BE27: 5000 | BI27: =BE27*SUM(BF27:BH27) -> 0 | BK27: 5000 | BO27: =BK27*SUM(BL27:BN27) -> 0 | BQ27: 5000 | BU27: =BQ27*SUM(BR27:BT27) -> 0 | BW27: 5000 | CA27: =BW27*SUM(BX27:BZ27) -> 0
A28: 3.5 | B28: Chấm bài trắc nghiệm: | C28: 2000 | D28: 52 | G28: =C28*SUM(D28:F28) -> 104000 | I28: 2000 | J28: 81 | M28: =I28*SUM(J28:L28) -> 162000 | O28: 2000 | S28: =O28*SUM(P28:R28) -> 0 | U28: 2000 | Y28: =U28*SUM(V28:X28) -> 0 | AA28: 2000 | AE28: =AA28*SUM(AB28:AD28) -> 0 | AG28: 2000 | AH28: 327 | AK28: =AG28*SUM(AH28:AJ28) -> 654000 | AM28: 2000 | AN28: 58 | AQ28: =AM28*SUM(AN28:AP28) -> 116000 | AS28: 2000 | AT28: 85 | AW28: =AS28*SUM(AT28:AV28) -> 170000 | AY28: 2000 | AZ28: 70 | BC28: =AY28*SUM(AZ28:BB28) -> 140000 | BE28: 2000 | BF28: 165 | BI28: =BE28*SUM(BF28:BH28) -> 330000 | BK28: 2000 | BL28: 44 | BO28: =BK28*SUM(BL28:BN28) -> 88000 | BQ28: 2000 | BR28: 145 | BU28: =BQ28*SUM(BR28:BT28) -> 290000 | BW28: 2000 | BX28: 35 | CA28: =BW28*SUM(BX28:BZ28) -> 70000
A29: 3.6 | B29: Giáo viên ra đề thi. | C29: 50000 | D29: 5 | G29: =C29*SUM(D29:F29) -> 250000 | I29: 50000 | J29: 5 | M29: =I29*SUM(J29:L29) -> 250000 | O29: 50000 | S29: =O29*SUM(P29:R29) -> 0 | U29: 50000 | V29: 7 | Y29: =U29*SUM(V29:X29) -> 350000 | AA29: 50000 | AB29: 9 | AE29: =AA29*SUM(AB29:AD29) -> 450000 | AG29: 50000 | AH29: 11 | AK29: =AG29*SUM(AH29:AJ29) -> 550000 | AM29: 50000 | AN29: 2 | AQ29: =AM29*SUM(AN29:AP29) -> 100000 | AS29: 50000 | AT29: 3 | AW29: =AS29*SUM(AT29:AV29) -> 150000 | AY29: 50000 | AZ29: 1 | BC29: =AY29*SUM(AZ29:BB29) -> 50000 | BE29: 50000 | BF29: 8 | BI29: =BE29*SUM(BF29:BH29) -> 400000 | BK29: 50000 | BL29: 2 | BO29: =BK29*SUM(BL29:BN29) -> 100000 | BQ29: 50000 | BR29: 4 | BU29: =BQ29*SUM(BR29:BT29) -> 200000 | BW29: 50000 | BX29: 2 | CA29: =BW29*SUM(BX29:BZ29) -> 100000
A30: 3.7 | B30: khác | G30: =C30+SUM(D30:F30) -> 0 | M30: =I30*SUM(J30:L30) -> 0 | S30: =O30*SUM(P30:R30) -> 0 | Y30: =U30*SUM(V30:X30) -> 0 | AE30: =AA30*SUM(AB30:AD30) -> 0 | AK30: =AG30*SUM(AH30:AJ30) -> 0 | AQ30: =AM30*SUM(AN30:AP30) -> 0 | AW30: =AS30*SUM(AT30:AV30) -> 0 | BC30: =17*40000 -> 680000 | BD30: trợ giảng 40k/t | BI30: =BE30*SUM(BF30:BH30) -> 0 | BO30: =BK30*SUM(BL30:BN30) -> 0 | BU30: =BQ30*SUM(BR30:BT30) -> 0 | CA30: =BW30*SUM(BX30:BZ30) -> 0
A31: 4 | B31: GIẢM TRỪ | G31: =SUM(G32:G35) -> 535500 | H31: =D31+E31+F31 -> 0 | M31: =SUM(M32:M35) -> 535500 | N31: =J31+K31+L31 -> 0 | S31: =SUM(S32:S35) -> 535500 | T31: =P31+Q31+R31 -> 0 | Y31: =SUM(Y32:Y35) -> 573142 | Z31: =V31+W31+X31 -> 0 | AE31: =SUM(AE32:AE35) -> 535500 | AF31: =AB31+AC31+AD31 -> 0 | AK31: =SUM(AK32:AK35) -> 535500 | AL31: =AH31+AI31+AJ31 -> 0 | AQ31: =SUM(AQ32:AQ35) -> 535500 | AR31: =AN31+AO31+AP31 -> 0 | AW31: =SUM(AW32:AW35) -> 535500 | AX31: =AT31+AU31+AV31 -> 0 | BC31: =SUM(BC32:BC35) -> 535500 | BD31: =AZ31+BA31+BB31 -> 0 | BI31: =SUM(BI32:BI35) -> 535500 | BJ31: =BF31+BG31+BH31 -> 0 | BO31: =SUM(BO32:BO35) -> 1632000 | BP31: =BL31+BM31+BN31 -> 0 | BU31: =SUM(BU32:BU35) -> 1632000 | BV31: =BR31+BS31+BT31 -> 0 | CA31: =SUM(CA32:CA35) -> 1780250 | CB31: =BX31+BY31+BZ31 -> 0
A32: 4.1 | B32: Trừ BHXH 10,5% (5,1tr/t) | G32: =5100000*10.5% -> 535500 | M32: =5100000*10.5% -> 535500 | S32: =5100000*10.5% -> 535500 | Y32: =5100000*10.5% -> 535500 | AE32: =5100000*10.5% -> 535500 | AK32: =5100000*10.5% -> 535500 | AQ32: =5100000*10.5% -> 535500 | AW32: =5100000*10.5% -> 535500 | BC32: =5100000*10.5% -> 535500 | BI32: =5100000*10.5% -> 535500 | BO32: =5100000*32% -> 1632000 | BP32: 32% nhờ đóng BHXH | BU32: =5100000*32% -> 1632000 | BV32: 32% nhờ đóng BHXH | CA32: =5100000*32% -> 1632000 | CB32: 32% nhờ đóng BHXH
A33: 4.2 | B33: Trừ ngày công (do nghỉ phép)
A34: 4.3 | B34: Trừ TNCN | Y34: 37642 | BP34: 2 nơi thu 10% không vượt 15,5 | CA34: =(CA6+CA10+CA23-535500)*10% -> 148250 | CB34: 2 nơi trừ 10%
A35: 4.4 | B35: Trừ khác
A36: 5 | B36: TỔNG THU NHẬP | G36: =G6+G10+G23-G31 -> 13818500 | M36: =M6+M10+M23-M31 -> 10876500 | S36: =S6+S10+S23-S31 -> 9752961.5 | Y36: =Y6+Y10+Y23-Y31 -> 11395191 | AE36: =AE6+AE10+AE23-AE31 -> 16858500 | AK36: =AK6+AK10+AK23-AK31 -> 7651833.1 | AQ36: =AQ6+AQ10+AQ23-AQ31 -> -119500 | AW36: =AW6+AW10+AW23-AW31 -> 1614500 | BC36: =BC6+BC10+BC23-BC31 -> 2047833.1 | BI36: =BI6+BI10+BI23-BI31 -> 2394500 | BO36: =BO6+BO10+BO23-BO31 -> -1244000 | BU36: =BU6+BU10+BU23-BU31 -> 3434000 | CA36: =CA6+CA10+CA23-CA31 -> 237750
B38: TỔNG LƯƠNG CẦN CHI | D38: =SUM(C36:CB36) -> 78718569
C50: 375053591 | I50: 833333647 | O50: 907490651 | U50: 984239687 | AA50: 948756448 | AG50: 915054235 | AM50: 939364073 | AS50: 985336577 | AY50: 932927632 | BE50: 919161717 | BK50: 917394401 | BQ50: 387049143 | BW50: 917922968

Sheet D. GV TT 
A2: STT | C2: 7 | I2: 7 | O2: 7 | U2: 7 | AA2: 7 | AG2: 7 | AM2: 7 | AS2: 7 | AY2: 7 | BE2: 7 | BK2: 7 | BQ2: 7 | BW2: 7 | CC2: 7 | CI2: 7
B3: TÊN NHÂN VIÊN | C3: NGUYỄN DIỄM MY | I3: NGUYỄN VĂN GIANG | O3: NGUYỄN VĂN VŨ | U3: CHUNG BẢO SƠN | AA3: NGUYỄN THỊ NHẬT THY | AG3: NGUYỄN THỤY NGỌC THANH LOAN | AM3: DƯƠNG HIỀN MINH | AS3: PHẠM KIM THOA | AY3: NGUYỄN VĂN THẾ | BE3: HUỲNH NGUYỄN MINH VY | BK3: ĐINH VĂN PHÚC | BQ3: HUỲNH TRÍ HIẾU | BW3: HUỲNH VĂN TÂY | CC3: PHẠM TRƯƠNG KIM DƯƠNG | CI3: NGUYỄN THỊ NGỌC PHÚC
B4: CHỨC VỤ | C4: GV SINH | I4: GV TIN | O4: GV SINH | U4: GV GDKT&PL | AA4: GV ÂM NHẠC | AG4: GV SỬ | AM4: GV ÂM NHẠC | AS4: GV SỬ | AY4: GV VẬT LÝ | BE4: GV VĂN | BK4: GV SỬ | BQ4: GV TOÁN | BW4: GV - GDCD | CC4: GV MỸ THUẬT | CI4: GV ĐỊA
C5: ĐG | D5: SL THPT | E5: SL NKCT | F5: SL BDVH | G5: TIỀN | H5: GHI CHÚ | I5: ĐG | J5: SL THPT | K5: SL NKCT | L5: SL BDVH | M5: TIỀN | N5: GHI CHÚ | O5: ĐG | P5: SL THPT | Q5: SL NKCT | R5: SL BDVH | S5: TIỀN | T5: GHI CHÚ | U5: ĐG | V5: SL THPT | W5: SL NKCT | X5: SL BDVH | Y5: TIỀN | Z5: GHI CHÚ | AA5: ĐG | AB5: SL THPT | AC5: SL NKCT | AD5: SL BDVH | AE5: TIỀN | AF5: GHI CHÚ | AG5: ĐG | AH5: SL THPT | AI5: SL NKCT | AJ5: SL BDVH | AK5: TIỀN | AL5: GHI CHÚ | AM5: ĐG | AN5: SL THPT | AO5: SL NKCT | AP5: SL BDVH | AQ5: TIỀN | AR5: GHI CHÚ | AS5: ĐG | AT5: SL THPT | AU5: SL NKCT | AV5: SL BDVH | AW5: TIỀN | AX5: GHI CHÚ | AY5: ĐG | AZ5: SL THPT | BA5: SL NKCT | BB5: SL BDVH | BC5: TIỀN | BD5: GHI CHÚ | BE5: ĐG | BF5: SL THPT | BG5: SL NKCT | BH5: SL BDVH | BI5: TIỀN | BJ5: GHI CHÚ | BK5: ĐG | BL5: SL THPT | BM5: SL NKCT | BN5: SL BDVH | BO5: TIỀN | BP5: GHI CHÚ | BQ5: ĐG | BR5: SL THPT | BS5: SL NKCT | BT5: SL BDVH | BU5: TIỀN | BV5: GHI CHÚ | BW5: ĐG | BX5: SL THPT | BY5: SL NKCT | BZ5: SL BDVH | CA5: TIỀN | CB5: GHI CHÚ | CC5: ĐG | CD5: SL THPT | CE5: SL NKCT | CF5: SL BDVH | CG5: TIỀN | CH5: GHI CHÚ | CI5: ĐG | CJ5: SL THPT | CK5: SL NKCT | CL5: SL BDVH | CM5: TIỀN | CN5: GHI CHÚ
A6: 1 | B6: LƯƠNG CHỨC VỤ, KIÊM NHIỆM | G6: =SUM(G7:G8) -> 1000000 | H6: =SUM(H7:H8) -> 0 | M6: =SUM(M7:M8) -> 0 | N6: =SUM(N7:N8) -> 0 | S6: =SUM(S7:S8) -> 0 | T6: =SUM(T7:T8) -> 0 | Y6: =SUM(Y7:Y8) -> 1000000 | Z6: =SUM(Z7:Z8) -> 0 | AE6: =SUM(AE7:AE8) -> 0 | AF6: =SUM(AF7:AF8) -> 0 | AK6: =SUM(AK7:AK8) -> 0 | AL6: =SUM(AL7:AL8) -> 0 | AQ6: =SUM(AQ7:AQ8) -> 1000000 | AR6: =SUM(AR7:AR8) -> 0 | AW6: =SUM(AW7:AW8) -> 0 | AX6: =SUM(AX7:AX8) -> 0 | BC6: =SUM(BC7:BC8) -> 0 | BD6: =SUM(BD7:BD8) -> 0 | BI6: =SUM(BI7:BI8) -> 0 | BJ6: =SUM(BJ7:BJ8) -> 0 | BO6: =SUM(BO7:BO8) -> 0 | BP6: =SUM(BP7:BP8) -> 0 | BU6: =SUM(BU7:BU8) -> 0 | BV6: =SUM(BV7:BV8) -> 0 | CA6: =SUM(CA7:CA8) -> 0 | CB6: =SUM(CB7:CB8) -> 0 | CG6: =SUM(CG7:CG8) -> 0 | CH6: =SUM(CH7:CH8) -> 0 | CM6: =SUM(CM7:CM8) -> 0 | CN6: =SUM(CN7:CN8) -> 0
A7: 1.1 | B7: Lương chức vụ
A8: 1.2 | B8: Kiêm nhiệm GVCN | G8: 1000000 | H8: NKCT L11 | Y8: 1000000 | Z8: NKCT L10 | AQ8: 1000000 | AR8: NKCT 8A2
A9: 1.3 | B9: Kiêm nhiệm khác
A10: 2 | B10: LƯƠNG TIẾT DẠY - TRƯỜNG THPT | D10: =SUM(D11:D18) -> 0 | E10: =SUM(E11:E18) -> 21 | F10: =SUM(F11:F18) -> 0 | G10: =SUM(G11:G19) -> 0 | H10: =D10+E10+F10 -> 21 | J10: =SUM(J11:J18) -> 0 | K10: =SUM(K11:K18) -> 27 | L10: =SUM(L11:L18) -> 0 | M10: =SUM(M11:M19) -> 120000 | N10: =J10+K10+L10 -> 27 | P10: =SUM(P11:P18) -> 0 | Q10: =SUM(Q11:Q18) -> 25 | R10: =SUM(R11:R18) -> 0 | S10: =SUM(S11:S19) -> 0 | T10: =P10+Q10+R10 -> 25 | V10: =SUM(V11:V18) -> 10 | W10: =SUM(W11:W18) -> 20 | X10: =SUM(X11:X18) -> 0 | Y10: =SUM(Y11:Y19) -> 1000000 | Z10: =V10+W10+X10 -> 30 | AB10: =SUM(AB11:AB18) -> 0 | AC10: =SUM(AC11:AC18) -> 0 | AD10: =SUM(AD11:AD18) -> 0 | AE10: =SUM(AE11:AE19) -> 0 | AF10: =AB10+AC10+AD10 -> 0 | AH10: =SUM(AH11:AH18) -> 0 | AI10: =SUM(AI11:AI18) -> 0 | AJ10: =SUM(AJ11:AJ18) -> 0 | AK10: =SUM(AK11:AK19) -> 0 | AL10: =AH10+AI10+AJ10 -> 0 | AN10: =SUM(AN11:AN18) -> 10 | AO10: =SUM(AO11:AO18) -> 44 | AP10: =SUM(AP11:AP18) -> 0 | AQ10: =SUM(AQ11:AQ19) -> 1000000 | AR10: =AN10+AO10+AP10 -> 54 | AT10: =SUM(AT11:AT18) -> 0 | AU10: =SUM(AU11:AU18) -> 40 | AV10: =SUM(AV11:AV18) -> 0 | AW10: =SUM(AW11:AW19) -> 0 | AX10: =AT10+AU10+AV10 -> 40 | AZ10: =SUM(AZ11:AZ18) -> 4 | BA10: =SUM(BA11:BA18) -> 48 | BB10: =SUM(BB11:BB18) -> 0 | BC10: =SUM(BC11:BC19) -> 400000 | BD10: =AZ10+BA10+BB10 -> 52 | BF10: =SUM(BF11:BF18) -> 0 | BG10: =SUM(BG11:BG18) -> 0 | BH10: =SUM(BH11:BH18) -> 0 | BI10: =SUM(BI11:BI19) -> 0 | BJ10: =BF10+BG10+BH10 -> 0 | BL10: =SUM(BL11:BL18) -> 0 | BM10: =SUM(BM11:BM18) -> 0 | BN10: =SUM(BN11:BN18) -> 0 | BO10: =SUM(BO11:BO19) -> 0 | BP10: =BL10+BM10+BN10 -> 0 | BR10: =SUM(BR11:BR18) -> 0 | BS10: =SUM(BS11:BS18) -> 14 | BT10: =SUM(BT11:BT18) -> 0 | BU10: =SUM(BU11:BU19) -> 0 | BV10: =BR10+BS10+BT10 -> 14 | BX10: =SUM(BX11:BX18) -> 0 | BY10: =SUM(BY11:BY18) -> 25 | BZ10: =SUM(BZ11:BZ18) -> 0 | CA10: =SUM(CA11:CA19) -> 0 | CB10: =BX10+BY10+BZ10 -> 25 | CD10: =SUM(CD11:CD18) -> 0 | CE10: =SUM(CE11:CE18) -> 0 | CF10: =SUM(CF11:CF18) -> 0 | CG10: =SUM(CG11:CG19) -> 0 | CH10: =CD10+CE10+CF10 -> 0 | CJ10: =SUM(CJ11:CJ18) -> 0 | CK10: =SUM(CK11:CK18) -> 16 | CL10: =SUM(CL11:CL18) -> 0 | CM10: =SUM(CM11:CM19) -> 0 | CN10: =CJ10+CK10+CL10 -> 16
A11: 2.1 | B11: Tiểu học ( lớp 1,2,3,4,5): | C11: 60000 | G11: =C11*(D11+E11+F11) -> 0 | H11: PT1 | I11: 60000 | K11: 2 | M11: =I11*(J11+K11+L11) -> 120000 | N11: PT1 | O11: 60000 | S11: =O11*(P11+Q11+R11) -> 0 | T11: PT1 | U11: 60000 | Y11: =U11*(V11+W11+X11) -> 0 | Z11: PT1 | AA11: 60000 | AE11: =AA11*(AB11+AC11+AD11) -> 0 | AF11: PT1 | AG11: 60000 | AK11: =AG11*(AH11+AI11+AJ11) -> 0 | AL11: PT1 | AM11: 60000 | AQ11: =AM11*(AN11+AO11+AP11) -> 0 | AR11: PT1 | AS11: 60000 | AW11: =AS11*(AT11+AU11+AV11) -> 0 | AX11: PT1 | AY11: 60000 | BC11: =AY11*(AZ11+BA11+BB11) -> 0 | BD11: PT1 | BE11: 60000 | BI11: =BE11*(BF11+BG11+BH11) -> 0 | BJ11: PT1 | BK11: 60000 | BO11: =BK11*(BL11+BM11+BN11) -> 0 | BP11: PT1 | BQ11: 60000 | BU11: =BQ11*(BR11+BS11+BT11) -> 0 | BV11: PT1 | BW11: 100000 | CA11: =BW11*(BX11+BY11+BZ11) -> 0 | CB11: 100K/ TIẾT, ( nếu có dạy L12 thì hỏi lại) | CC11: 60000 | CG11: =CC11*(CD11+CE11+CF11) -> 0 | CH11: PT1 | CI11: 60000 | CM11: =CI11*(CJ11+CK11+CL11) -> 0 | CN11: PT1
A12: 2.2 | B12: THCS (lớp 6,7,8): | G12: =C12*(D12+E12+F12) -> 0 | K12: 18 | M12: =I12*(J12+K12+L12) -> 0 | Q12: 3 | S12: =O12*(P12+Q12+R12) -> 0 | Y12: =U12*(V12+W12+X12) -> 0 | AE12: =AA12*(AB12+AC12+AD12) -> 0 | AK12: =AG12*(AH12+AI12+AJ12) -> 0 | AO12: =6+12+14 -> 32 | AQ12: =AM12*(AN12+AO12+AP12) -> 0 | AU12: =3+8+8 -> 19 | AW12: =AS12*(AT12+AU12+AV12) -> 0 | BA12: =8+14+18 -> 40 | BC12: =AY12*(AZ12+BA12+BB12) -> 0 | BI12: =BE12*(BF12+BG12+BH12) -> 0 | BO12: =BK12*(BL12+BM12+BN12) -> 0 | BU12: =BQ12*(BR12+BS12+BT12) -> 0 | BY12: 17 | CA12: =BW12*(BX12+BY12+BZ12) -> 0 | CG12: =CC12*(CD12+CE12+CF12) -> 0 | CM12: =CI12*(CJ12+CK12+CL12) -> 0
A13: 2.3 | B13: THCS (lớp 9): | E13: 15 | G13: =C13*(D13+E13+F13) -> 0 | M13: =I13*(J13+K13+L13) -> 0 | Q13: 6 | S13: =O13*(P13+Q13+R13) -> 0 | Y13: =U13*(V13+W13+X13) -> 0 | AE13: =AA13*(AB13+AC13+AD13) -> 0 | AK13: =AG13*(AH13+AI13+AJ13) -> 0 | AO13: 12 | AQ13: =AM13*(AN13+AO13+AP13) -> 0 | AU13: 6 | AW13: =AS13*(AT13+AU13+AV13) -> 0 | BA13: 8 | BC13: =AY13*(AZ13+BA13+BB13) -> 0 | BI13: =BE13*(BF13+BG13+BH13) -> 0 | BO13: =BK13*(BL13+BM13+BN13) -> 0 | BU13: =BQ13*(BR13+BS13+BT13) -> 0 | BY13: 8 | CA13: =BW13*(BX13+BY13+BZ13) -> 0 | CG13: =CC13*(CD13+CE13+CF13) -> 0 | CM13: =CI13*(CJ13+CK13+CL13) -> 0
A14: 2.4 | B14: THPT (lớp 10,11): | E14: 6 | G14: =C14*(D14+E14+F14) -> 0 | M14: =I14*(J14+K14+L14) -> 0 | Q14: 8 | S14: =O14*(P14+Q14+R14) -> 0 | W14: 14 | Y14: =U14*(V14+W14+X14) -> 0 | AE14: =AA14*(AB14+AC14+AD14) -> 0 | AK14: =AG14*(AH14+AI14+AJ14) -> 0 | AQ14: =AM14*(AN14+AO14+AP14) -> 0 | AU14: 10 | AW14: =AS14*(AT14+AU14+AV14) -> 0 | BC14: =AY14*(AZ14+BA14+BB14) -> 0 | BI14: =BE14*(BF14+BG14+BH14) -> 0 | BO14: =BK14*(BL14+BM14+BN14) -> 0 | BS14: 14 | BU14: =BQ14*(BR14+BS14+BT14) -> 0 | CA14: =BW14*(BX14+BY14+BZ14) -> 0 | CG14: =CC14*(CD14+CE14+CF14) -> 0 | CK14: =4+12 -> 16 | CM14: =CI14*(CJ14+CK14+CL14) -> 0
A15: 2.5 | B15: THPT (lớp 12): | G15: =C15*(D15+E15+F15) -> 0 | K15: 7 | M15: =I15*(J15+K15+L15) -> 0 | Q15: 8 | S15: =O15*(P15+Q15+R15) -> 0 | W15: 6 | Y15: =U15*(V15+W15+X15) -> 0 | AE15: =AA15*(AB15+AC15+AD15) -> 0 | AK15: =AG15*(AH15+AI15+AJ15) -> 0 | AQ15: =AM15*(AN15+AO15+AP15) -> 0 | AU15: 5 | AW15: =AS15*(AT15+AU15+AV15) -> 0 | BC15: =AY15*(AZ15+BA15+BB15) -> 0 | BI15: =BE15*(BF15+BG15+BH15) -> 0 | BO15: =BK15*(BL15+BM15+BN15) -> 0 | BU15: =BQ15*(BR15+BS15+BT15) -> 0 | CA15: =BW15*(BX15+BY15+BZ15) -> 0 | CG15: =CC15*(CD15+CE15+CF15) -> 0 | CM15: =CI15*(CJ15+CK15+CL15) -> 0
A16: 2.6 | B16: Hoạt động ngoại khóa | C16: 100000 | G16: =C16*(D16+E16+F16) -> 0 | I16: 100000 | M16: =I16*(J16+K16+L16) -> 0 | O16: 100000 | S16: =O16*(P16+Q16+R16) -> 0 | U16: 100000 | V16: 10 | Y16: =U16*(V16+W16+X16) -> 1000000 | AA16: 100000 | AE16: =AA16*(AB16+AC16+AD16) -> 0 | AG16: 100000 | AK16: =AG16*(AH16+AI16+AJ16) -> 0 | AM16: 100000 | AN16: 10 | AQ16: =AM16*(AN16+AO16+AP16) -> 1000000 | AS16: 100000 | AW16: =AS16*(AT16+AU16+AV16) -> 0 | AY16: 100000 | AZ16: 4 | BC16: =AY16*(AZ16+BA16+BB16) -> 400000 | BE16: 100000 | BI16: =BE16*(BF16+BG16+BH16) -> 0 | BK16: 100000 | BO16: =BK16*(BL16+BM16+BN16) -> 0 | BQ16: 100000 | BU16: =BQ16*(BR16+BS16+BT16) -> 0 | BW16: 100000 | CA16: =BW16*(BX16+BY16+BZ16) -> 0 | CC16: 100000 | CG16: =CC16*(CD16+CE16+CF16) -> 0 | CI16: 100000 | CM16: =CI16*(CJ16+CK16+CL16) -> 0
A17: 2.7 | B17: Quản học (70% lương của tiết học) | C17: 92500 | G17: =C17*(D17+E17+F17) -> 0 | I17: 92500 | M17: =I17*(J17+K17+L17) -> 0 | O17: 92500 | S17: =O17*(P17+Q17+R17) -> 0 | U17: 92500 | Y17: =U17*(V17+W17+X17) -> 0 | AA17: 92500 | AE17: =AA17*(AB17+AC17+AD17) -> 0 | AG17: 92500 | AK17: =AG17*(AH17+AI17+AJ17) -> 0 | AM17: 92500 | AQ17: =AM17*(AN17+AO17+AP17) -> 0 | AS17: 92500 | AW17: =AS17*(AT17+AU17+AV17) -> 0 | AY17: 92500 | BC17: =AY17*(AZ17+BA17+BB17) -> 0 | BE17: 92500 | BI17: =BE17*(BF17+BG17+BH17) -> 0 | BK17: 92500 | BO17: =BK17*(BL17+BM17+BN17) -> 0 | BQ17: 92500 | BU17: =BQ17*(BR17+BS17+BT17) -> 0 | BW17: 92500 | CA17: =BW17*(BX17+BY17+BZ17) -> 0 | CC17: 92500 | CG17: =CC17*(CD17+CE17+CF17) -> 0 | CI17: 92500 | CM17: =CI17*(CJ17+CK17+CL17) -> 0
A18: 2.8 | B18: Lương dạy ( đủ đk nhận lương cơ hữu) | G18: =C18*(D18+E18+F18) -> 0 | M18: =I18*(J18+K18+L18) -> 0 | S18: =O18*(P18+Q18+R18) -> 0 | Y18: =U18*(V18+W18+X18) -> 0 | AE18: =AA18*(AB18+AC18+AD18) -> 0 | AK18: =AG18*(AH18+AI18+AJ18) -> 0 | AQ18: =AM18*(AN18+AO18+AP18) -> 0 | AW18: =AS18*(AT18+AU18+AV18) -> 0 | BC18: =AY18*(AZ18+BA18+BB18) -> 0 | BI18: =BE18*(BF18+BG18+BH18) -> 0 | BO18: =BK18*(BL18+BM18+BN18) -> 0 | BU18: =BQ18*(BR18+BS18+BT18) -> 0 | CA18: =BW18*(BX18+BY18+BZ18) -> 0 | CG18: =CC18*(CD18+CE18+CF18) -> 0 | CM18: =CI18*(CJ18+CK18+CL18) -> 0
A19: 2.9 | B19: Số tiết dư được tạm ứng | C19: 100000 | G19: =C19*(D19+E19+F19) -> 0 | I19: 100000 | M19: =I19*(J19+K19+L19) -> 0 | O19: 100000 | S19: =O19*(P19+Q19+R19) -> 0 | U19: 100000 | Y19: =U19*(V19+W19+X19) -> 0 | AA19: 100000 | AE19: =AA19*(AB19+AC19+AD19) -> 0 | AG19: 100000 | AK19: =AG19*(AH19+AI19+AJ19) -> 0 | AM19: 100000 | AQ19: =AM19*(AN19+AO19+AP19) -> 0 | AS19: 100000 | AW19: =AS19*(AT19+AU19+AV19) -> 0 | AY19: 100000 | BC19: =AY19*(AZ19+BA19+BB19) -> 0 | BE19: 100000 | BI19: =BE19*(BF19+BG19+BH19) -> 0 | BK19: 100000 | BO19: =BK19*(BL19+BM19+BN19) -> 0 | BQ19: 100000 | BU19: =BQ19*(BR19+BS19+BT19) -> 0 | BW19: 100000 | CA19: =BW19*(BX19+BY19+BZ19) -> 0 | CC19: 100000 | CG19: =CC19*(CD19+CE19+CF19) -> 0 | CI19: 100000 | CM19: =CI19*(CJ19+CK19+CL19) -> 0
A20: 3 | B20: THU NHẬP TĂNG THÊM | D20: =SUM(D21:D29) -> 125.66667 | E20: =SUM(E21:E29) -> 0 | F20: =SUM(F21:F29) -> 0 | G20: =SUM(G21:G27) -> 1162666.7 | J20: =SUM(J21:J29) -> 138 | K20: =SUM(K21:K29) -> 0 | L20: =SUM(L21:L29) -> 0 | M20: =SUM(M21:M27) -> 1002000 | Q20: =SUM(Q21:Q29) -> 0 | R20: =SUM(R21:R29) -> 0 | S20: =SUM(S21:S27) -> 980000 | W20: =SUM(W21:W29) -> 0 | X20: =SUM(X21:X29) -> 0 | Y20: =SUM(Y21:Y27) -> 1732000 | AB20: =SUM(AB21:AB29) -> 0 | AC20: =SUM(AC21:AC29) -> 0 | AD20: =SUM(AD21:AD29) -> 0 | AE20: =SUM(AE21:AE27) -> 0 | AI20: =SUM(AI21:AI29) -> 0 | AJ20: =SUM(AJ21:AJ29) -> 0 | AK20: =SUM(AK21:AK27) -> 360000 | AO20: =SUM(AO21:AO29) -> 0 | AP20: =SUM(AP21:AP29) -> 0 | AQ20: =SUM(AQ21:AQ27) -> 1905333.1 | AU20: =SUM(AU21:AU29) -> 0 | AV20: =SUM(AV21:AV29) -> 0 | AW20: =SUM(AW21:AW27) -> 816000 | AZ20: =SUM(AZ21:AZ29) -> 135 | BA20: =SUM(BA21:BA29) -> 0 | BB20: =SUM(BB21:BB29) -> 0 | BC20: =SUM(BC21:BC27) -> 612000 | BF20: =SUM(BF21:BF29) -> 1 | BG20: =SUM(BG21:BG29) -> 0 | BH20: =SUM(BH21:BH29) -> 0 | BI20: =SUM(BI21:BI26) -> 200000 | BL20: =SUM(BL21:BL29) -> 39 | BM20: =SUM(BM21:BM29) -> 0 | BN20: =SUM(BN21:BN29) -> 0 | BO20: =SUM(BO21:BO27) -> 372000 | BR20: =SUM(BR21:BR29) -> 32 | BS20: =SUM(BS21:BS29) -> 0 | BT20: =SUM(BT21:BT29) -> 0 | BU20: =SUM(BU21:BU27) -> 310000 | BX20: =SUM(BX21:BX29) -> 264 | BY20: =SUM(BY21:BY29) -> 0 | BZ20: =SUM(BZ21:BZ29) -> 0 | CA20: =SUM(CA21:CA27) -> 1062000 | CD20: =SUM(CD21:CD29) -> 0 | CE20: =SUM(CE21:CE29) -> 0 | CF20: =SUM(CF21:CF29) -> 0 | CG20: =SUM(CG21:CG27) -> 0 | CJ20: =SUM(CJ21:CJ29) -> 63 | CK20: =SUM(CK21:CK29) -> 0 | CL20: =SUM(CL21:CL29) -> 0 | CM20: =SUM(CM21:CM27) -> 222000
A21: 3.1 | B21: Tăng ca làm thêm công | G21: =C21*SUM(D21:F21) -> 0 | M21: =I21*SUM(J21:L21) -> 0 | S21: =O21*SUM(P21:R21) -> 0 | Y21: =U21*SUM(V21:X21) -> 0 | AE21: =AA21*SUM(AB21:AD21) -> 0 | AK21: =AG21*SUM(AH21:AJ21) -> 0 | AQ21: =AM21*SUM(AN21:AP21) -> 0 | AW21: =AS21*SUM(AT21:AV21) -> 0 | BC21: =AY21*SUM(AZ21:BB21) -> 0 | BI21: =BE21*SUM(BF21:BH21) -> 0 | BO21: =BK21*SUM(BL21:BN21) -> 0 | BU21: =BQ21*SUM(BR21:BT21) -> 0 | CA21: =BW21*SUM(BX21:BZ21) -> 0 | CG21: =CC21*SUM(CD21:CF21) -> 0 | CM21: =CI21*SUM(CJ21:CL21) -> 0
A22: 3.2 | B22: Họp hội đồng sư phạm | C22: 200000 | D22: 1 | G22: =C22*SUM(D22:F22) -> 200000 | I22: 200000 | J22: 1 | M22: =I22*SUM(J22:L22) -> 200000 | O22: 200000 | P22: 1 | S22: =O22*SUM(P22:R22) -> 200000 | U22: 200000 | V22: 1 | Y22: =U22*SUM(V22:X22) -> 200000 | AA22: 200000 | AE22: =AA22*SUM(AB22:AD22) -> 0 | AG22: 200000 | AK22: =AG22*SUM(AH22:AJ22) -> 0 | AM22: 200000 | AN22: 1 | AQ22: =AM22*SUM(AN22:AP22) -> 200000 | AS22: 200000 | AT22: 1 | AW22: =AS22*SUM(AT22:AV22) -> 200000 | AY22: 200000 | AZ22: 1 | BC22: =AY22*SUM(AZ22:BB22) -> 200000 | BE22: 200000 | BF22: 1 | BI22: =BE22*SUM(BF22:BH22) -> 200000 | BK22: 200000 | BL22: 1 | BO22: =BK22*SUM(BL22:BN22) -> 200000 | BQ22: 200000 | BR22: 1 | BU22: =BQ22*SUM(BR22:BT22) -> 200000 | BW22: 200000 | BX22: 1 | CA22: =BW22*SUM(BX22:BZ22) -> 200000 | CC22: 200000 | CG22: =CC22*SUM(CD22:CF22) -> 0 | CI22: 200000 | CM22: =CI22*SUM(CJ22:CL22) -> 0
A23: 3.3 | B23: Gác thi (70%/LCB tiết dạy) ( hỏi lại) | C23: =70%*100000 -> 70000 | D23: 7.6666667 | G23: =C23*SUM(D23:F23) -> 536666.67 | I23: =70%*100000 -> 70000 | M23: =I23*SUM(J23:L23) -> 0 | O23: =70%*100000 -> 70000 | S23: =O23*SUM(P23:R23) -> 0 | U23: =70%*100000 -> 70000 | V23: 11 | Y23: =U23*SUM(V23:X23) -> 770000 | AA23: =70%*100000 -> 70000 | AE23: =AB23*AC23 -> 0 | AG23: =70%*100000 -> 70000 | AK23: =AG23*SUM(AH23:AJ23) -> 0 | AM23: =70%*100000 -> 70000 | AN23: 17.33333 | AQ23: =AM23*SUM(AN23:AP23) -> 1213333.1 | AS23: =70%*100000 -> 70000 | AW23: =AS23*SUM(AT23:AV23) -> 0 | AY23: =70%*100000 -> 70000 | BC23: =AY23*SUM(AZ23:BB23) -> 0 | BE23: =70%*100000 -> 70000 | BI23: =BE23*SUM(BF23:BH23) -> 0 | BK23: =70%*100000 -> 70000 | BO23: =BK23*SUM(BL23:BN23) -> 0 | BQ23: =70%*100000 -> 70000 | BU23: =BQ23*SUM(BR23:BT23) -> 0 | BW23: =70%*100000 -> 70000 | CA23: =BW23*SUM(BX23:BZ23) -> 0 | CC23: =70%*100000 -> 70000 | CG23: =CC23*SUM(CD23:CF23) -> 0 | CI23: =70%*100000 -> 70000 | CM23: =CI23*SUM(CJ23:CL23) -> 0
A24: 3.4 | B24: Chấm bài tự luận : | C24: 5000 | G24: =C24*SUM(D24:F24) -> 0 | I24: 5000 | M24: =I24*SUM(J24:L24) -> 0 | O24: 5000 | S24: =O24*SUM(P24:R24) -> 0 | U24: 5000 | Y24: =U24*SUM(V24:X24) -> 0 | AA24: 5000 | AE24: =AB24*AC24 -> 0 | AG24: 5000 | AK24: =AG24*SUM(AH24:AJ24) -> 0 | AM24: 5000 | AQ24: =AM24*SUM(AN24:AP24) -> 0 | AS24: 5000 | AW24: =AS24*SUM(AT24:AV24) -> 0 | AY24: 5000 | BC24: =AY24*SUM(AZ24:BB24) -> 0 | BE24: 5000 | BI24: =BE24*SUM(BF24:BH24) -> 0 | BK24: 5000 | BO24: =BK24*SUM(BL24:BN24) -> 0 | BQ24: 5000 | BU24: =BQ24*SUM(BR24:BT24) -> 0 | BW24: 5000 | CA24: =BW24*SUM(BX24:BZ24) -> 0 | CC24: 5000 | CG24: =CC24*SUM(CD24:CF24) -> 0 | CI24: 5000 | CM24: =CI24*SUM(CJ24:CL24) -> 0
A25: 3.5 | B25: Chấm bài trắc nghiệm: | C25: 2000 | D25: 113 | G25: =C25*SUM(D25:F25) -> 226000 | I25: 2000 | J25: 126 | M25: =I25*SUM(J25:L25) -> 252000 | O25: 2000 | P25: 190 | S25: =O25*SUM(P25:R25) -> 380000 | U25: 2000 | V25: 156 | Y25: =U25*SUM(V25:X25) -> 312000 | AA25: 2000 | AE25: =AB25*AC25 -> 0 | AG25: 2000 | AH25: 80 | AK25: =AG25*SUM(AH25:AJ25) -> 160000 | AM25: 2000 | AN25: 121 | AQ25: =AM25*SUM(AN25:AP25) -> 242000 | AS25: 2000 | AT25: 133 | AW25: =AS25*SUM(AT25:AV25) -> 266000 | AY25: 2000 | AZ25: 131 | BC25: =AY25*SUM(AZ25:BB25) -> 262000 | BE25: 2000 | BI25: =BE25*SUM(BF25:BH25) -> 0 | BK25: 2000 | BL25: 36 | BO25: =BK25*SUM(BL25:BN25) -> 72000 | BQ25: 2000 | BR25: 30 | BU25: =BQ25*SUM(BR25:BT25) -> 60000 | BW25: 2000 | BX25: 256 | CA25: =BW25*SUM(BX25:BZ25) -> 512000 | CC25: 2000 | CG25: =CC25*SUM(CD25:CF25) -> 0 | CI25: 2000 | CJ25: 61 | CM25: =CI25*SUM(CJ25:CL25) -> 122000
A26: 3.6 | B26: Giáo viên ra đề thi. | C26: 50000 | D26: 4 | G26: =C26*SUM(D26:F26) -> 200000 | I26: 50000 | J26: 11 | M26: =I26*SUM(J26:L26) -> 550000 | O26: 50000 | P26: 8 | S26: =O26*SUM(P26:R26) -> 400000 | U26: 50000 | V26: 9 | Y26: =U26*SUM(V26:X26) -> 450000 | AA26: 50000 | AE26: =AB26*AC26 -> 0 | AG26: 50000 | AH26: 4 | AK26: =AG26*SUM(AH26:AJ26) -> 200000 | AM26: 50000 | AN26: 5 | AQ26: =AM26*SUM(AN26:AP26) -> 250000 | AS26: 50000 | AT26: 7 | AW26: =AS26*SUM(AT26:AV26) -> 350000 | AY26: 50000 | AZ26: 3 | BC26: =AY26*SUM(AZ26:BB26) -> 150000 | BE26: 50000 | BI26: =BE26*SUM(BF26:BH26) -> 0 | BK26: 50000 | BL26: 2 | BO26: =BK26*SUM(BL26:BN26) -> 100000 | BQ26: 50000 | BR26: 1 | BU26: =BQ26*SUM(BR26:BT26) -> 50000 | BW26: 50000 | BX26: 7 | CA26: =BW26*SUM(BX26:BZ26) -> 350000 | CC26: 50000 | CG26: =CC26*SUM(CD26:CF26) -> 0 | CI26: 50000 | CJ26: 2 | CM26: =CI26*SUM(CJ26:CL26) -> 100000
A27: 3.7 | B27: khác | G27: =C27*SUM(D27:F27) -> 0 | M27: =I27*SUM(J27:L27) -> 0 | S27: =O27*SUM(P27:R27) -> 0 | Y27: =U27*SUM(V27:X27) -> 0 | AK27: =AG27*SUM(AH27:AJ27) -> 0 | AQ27: =AM27*SUM(AN27:AP27) -> 0 | AW27: =AS27*SUM(AT27:AV27) -> 0 | BC27: =AY27*SUM(AZ27:BB27) -> 0 | BI27: =BE27*SUM(BF27:BH27) -> 0 | BO27: =BK27*SUM(BL27:BN27) -> 0 | BU27: =BQ27*SUM(BR27:BT27) -> 0 | CA27: =BW27*SUM(BX27:BZ27) -> 0 | CG27: =CC27*SUM(CD27:CF27) -> 0 | CM27: =CI27*SUM(CJ27:CL27) -> 0
A28: 4 | B28: GIẢM TRỪ | G28: =SUM(G29:G31) -> 216266.67 | H28: =D28+E28+F28 -> 0 | M28: =SUM(M29:M31) -> 112200 | N28: =J28+K28+L28 -> 0 | S28: =SUM(S29:S31) -> 98000 | T28: =P28+Q28+R28 -> 0 | Y28: =SUM(Y29:Y31) -> 0 | Z28: =V28+W28+X28 -> 0 | AE28: =SUM(AE29:AE31) -> 0 | AF28: =AB28+AC28+AD28 -> 0 | AK28: =SUM(AK29:AK31) -> 36000 | AL28: =AH28+AI28+AJ28 -> 0 | AQ28: =SUM(AQ29:AQ31) -> 0 | AR28: =AN28+AO28+AP28 -> 0 | AW28: =SUM(AW29:AW31) -> 81600 | AX28: =AT28+AU28+AV28 -> 0 | BC28: =SUM(BC29:BC31) -> 0 | BD28: =AZ28+BA28+BB28 -> 0 | BI28: =SUM(BI29:BI31) -> 0 | BJ28: =BF28+BG28+BH28 -> 0 | BO28: =SUM(BO29:BO31) -> 0 | BP28: =BL28+BM28+BN28 -> 0 | BU28: =SUM(BU29:BU31) -> 0 | BV28: =BR28+BS28+BT28 -> 0 | CA28: =SUM(CA29:CA31) -> 0 | CB28: =BX28+BY28+BZ28 -> 0 | CG28: =SUM(CG29:CG31) -> 0 | CH28: =CD28+CE28+CF28 -> 0 | CM28: =SUM(CM29:CM31) -> 22200 | CN28: =CJ28+CK28+CL28 -> 0
A29: 4.1 | B29: Trừ ngày công (do nghỉ phép)
A30: 4.2 | B30: Trừ TNCN (10%/ lương) | G30: =(G6+G10+G20)*10% -> 216266.67 | H30: 2 nơi thu 10% | M30: =(M6+M10+M20)*10% -> 112200 | N30: 2 nơi thu 10% | S30: =(S6+S10+S20)*10% -> 98000 | T30: 2 nơi thu 10% | AF30: 2 nơi thu 10% không vượt 15,5tr | AK30: =(AK6+AK10+AK20)*10% -> 36000 | AL30: 2 nơi thu 10% | AW30: =(AW6+AW10+AW20)*10% -> 81600 | AX30: 2 nơi thu 10% | BJ30: 2 nơi thu 10%, không vượt 15,5tr | CG30: =(CG6+CG10+CG20)*10% -> 0 | CH30: 2 nơi thu 10% | CM30: =(CM6+CM10+CM20)*10% -> 22200 | CN30: 2 nơi thu 10%
A31: 4.3 | B31: Trừ khác
A32: 5 | B32: TỔNG THU NHẬP | G32: =G6+G10+G20-G28 -> 1946400 | M32: =M6+M10+M20-M28 -> 1009800 | S32: =S6+S10+S20-S28 -> 882000 | Y32: =Y6+Y10+Y20-Y28 -> 3732000 | AE32: =AE6+AE10+AE20-AE28 -> 0 | AK32: =AK6+AK10+AK20-AK28 -> 324000 | AQ32: =AQ6+AQ10+AQ20-AQ28 -> 3905333.1 | AW32: =AW6+AW10+AW20-AW28 -> 734400 | BC32: =BC6+BC10+BC20-BC28 -> 1012000 | BI32: =BI6+BI10+BI20-BI28 -> 200000 | BO32: =BO6+BO10+BO20-BO28 -> 372000 | BU32: =BU6+BU10+BU20-BU28 -> 310000 | CA32: =CA6+CA10+CA20-CA28 -> 1062000 | CG32: =CG6+CG10+CG20-CG28 -> 0 | CM32: =CM6+CM10+CM20-CM28 -> 199800
B34: TỔNG LƯƠNG CẦN CHI | D34: =SUM(C32:CN32) -> 15689733
C50: 941606447 | I50: 939961626 | O50: 989499585 | U50: 348399870 | AA50: 907271001 | AG50: 939647899 | AM50: 947114309 | AS50: 778602585 | AY50: 582255388 | BE50: 917189549 | BK50: 944100099 | BQ50: 913642605 | BW50: 981634458 | CC50: 0939331585 | CI50: 979386993
